<mujoco model="walker_telescopic-v0">
  <compiler angle="degree" coordinate="global" inertiafromgeom="true"/>
  <default>
    <joint armature="1" damping="1" limited="true"/>
    <geom conaffinity="1" condim="1" contype="1" margin="0.001" material="geom" rgba="0.8 0.6 0.4 1" solimp=".8 .8 .01" solref=".02 1"/>
    <motor ctrllimited="true" ctrlrange="-0.4 0.4"/>
  </default>
  <option integrator="RK4" timestep="0.002"/>
  <visual>
    <map znear="0.02"/>
  </visual>
  <worldbody>
    <light cutoff="100" diffuse="1 1 1" dir="-0 0 -1.3" directional="true" exponent="1" pos="0 0 1.3" specular="0.1 0.1 0.1"/>
    <geom conaffinity="1" condim="3" name="floor" pos="0 0 0" rgba="0.8 0.9 0.8 1" size="20 20 0.125" type="plane" material="MatPlane"/>
    <body name="torso" pos="0 0 1.0">
      <camera name="track" mode="trackcom" pos="0 -3 1" xyaxes="1 0 0 0 0 1"/>
      <camera name="track_front" mode="trackcom" pos="-3 0 1" xyaxes="0 -1 0 0 0 1"/>
      <camera name="track_top" mode="trackcom" pos="0 0 3" xyaxes="0 1 0 -1 0 0"/>
      <joint armature="0" axis="1 0 0" damping="0" limited="false" name="rootx" pos="0 0 0" stiffness="0" type="slide"/>
      <joint armature="0" axis="0 0 1" damping="0" limited="false" name="rootz" pos="0 0 0" ref="1" stiffness="0" type="slide"/>
      <geom friction="0.9" pos="0 0 1.0" size="0.15" name="torso_geom" type="sphere"/>
      <body name="tiny_head" pos="0 0 1.2">
        <geom friction="0.9" pos="0 0 1.2" size="0.05" name="head_geom" type="sphere" rgba="1 0 0 1"/>
      </body>
      <body name="thigh_left" pos="0 0.2 1.0">
        <joint axis="0 -1 0" name="thigh_left_joint" pos="0 0.2 1.0" range="-90 90" type="hinge"/>
        <geom friction="0.9" fromto="0 0.2 1.05 0 0.2 0.6" name="thigh_left_geom" size="0.05" type="capsule"/>
        <body name="shin_left" pos="0 0.2 0.6">
          <joint axis="0 0 -1" name="shin_left_joint" pos="0 0.2 0.6" range="-0.05 0.05" type="slide"/>
          <geom friction="0.9" fromto="0 0.2 0.6 0 0.2 0" name="shin_left_geom" size="0.04" type="capsule"/>
          <body name="foot_left" pos="0 0.2 0">
            <site name="toe_left" type="sphere" size="0.05" rgba="0 1 0 1" pos="0 0.2 0"/>
          </body>
        </body>
      </body>
      <body name="thigh_right" pos="0 -0.2 1.0">
        <joint axis="0 -1 0" name="thigh_right_joint" pos="0 -0.2 1.0" range="-90 90" type="hinge"/>
        <geom friction="0.9" fromto="0 -0.2 1.05 0 -0.2 0.6" name="thigh_right_geom" size="0.05" type="capsule"/>
        <body name="shin_right" pos="0 -0.2 0.6">
          <joint axis="0 0 -1" name="shin_right_joint" pos="0 -0.2 0.6" range="-0.05 0.05" type="slide"/>
          <geom friction="0.9" fromto="0 -0.2 0.6 0 -0.2 0" name="shin_right_geom" size="0.04" type="capsule"/>
          <body name="foot_right" pos="0 -0.2 0">
            <site name="toe_right" type="sphere" size="0.05" rgba="0 1 0 1" pos="0 -0.2 0"/>
          </body>
        </body>
      </body>
    </body>
  </worldbody>
  <actuator>
    <motor ctrllimited="true" ctrlrange="-1.0 1.0" gear="50000.0" joint="thigh_left_joint"/>
    <motor ctrllimited="true" ctrlrange="-1.0 1.0" gear="50000.0" joint="thigh_right_joint"/>
    <motor ctrllimited="true" ctrlrange="-1.0 1.0" gear="20000.0" joint="shin_left_joint"/>
    <motor ctrllimited="true" ctrlrange="-1.0 1.0" gear="20000.0" joint="shin_right_joint"/>
  </actuator>
    <asset>
      <texture type="skybox" builtin="gradient" rgb1="0.4 0.5 0.6" rgb2="0 0 0" width="100" height="100"/>
      <texture builtin="flat" height="1278" mark="cross" markrgb="1 1 1" name="texgeom" random="0.01" rgb1="0.8 0.6 0.4" rgb2="0.8 0.6 0.4" type="cube" width="127"/>
      <texture builtin="checker" height="100" name="texplane" rgb1="0 0 0" rgb2="0.8 0.8 0.8" type="2d" width="100"/>
      <material name="MatPlane" reflectance="0.5" shininess="1" specular="1" texrepeat="60 60" texture="texplane"/>
      <material name="geom" texture="texgeom" texuniform="true"/>
  </asset>
</mujoco>
